Workbook

Sheet MovieFinancials
A1: Movie ID | B1: Movie Title | C1: Industry | D1: Release Year | E1: IMDb Rating | F1: Studio | G1: Language ID | H1: Budget (Original) | I1: Revenue (Original) | J1: Unit | K1: Currency | L1: Unit Factor | M1: Budget (Millions) | N1: Revenue (Millions) | O1: Budget (INR mm) | P1: Revenue (INR mm) | Q1: Budget (USD mm) | R1: Revenue (USD mm) | S1: ROI% | T1: Watch Verdict
A2: 128 | B2: Taare Zameen Par | C2: Bollywood | D2: 2007 | E2: 8.3 | F2: Not Available | G2: 1 | H2: 120 | I2: 1350 | J2: Millions | K2: INR | L2: =IF(J2="","",IF(J2="Billions",1000,1)) -> 1 | M2: =IF(H2="","",H2*L2) -> 120 | N2: =IF(I2="","",I2*L2) -> 1350 | O2: =IF(M2="","",IF(K2="INR",M2,M2*80)) -> 120 | P2: =IF(N2="","",IF(K2="INR",N2,N2*80)) -> 1350 | Q2: =IF(M2="","",IF(K2="INR",M2/80,M2)) -> 1.5 | R2: =IF(N2="","",IF(K2="INR",N2/80,N2)) -> 16.875 | S2: =IF(OR(Q2="",R2="",Q2=0),"",(R2-Q2)/Q2) -> 10.25 | T2: =IF(OR(E2="",E2=0),"Not Rated",IF(E2>=8,"Must Watch",IF(E2>=6,"Worth a watch","Skip"))) -> Must Watch
A3: 130 | B3: PK | C3: Bollywood | D3: 2014 | E3: 8.1 | F3: Vinod Chopra Films | G3: 1 | H3: 850 | I3: 8540 | J3: Millions | K3: INR | L3: =IF(J3="","",IF(J3="Billions",1000,1)) -> 1 | M3: =IF(H3="","",H3*L3) -> 850 | N3: =IF(I3="","",I3*L3) -> 8540 | O3: =IF(M3="","",IF(K3="INR",M3,M3*80)) -> 850 | P3: =IF(N3="","",IF(K3="INR",N3,N3*80)) -> 8540 | Q3: =IF(M3="","",IF(K3="INR",M3/80,M3)) -> 10.625 | R3: =IF(N3="","",IF(K3="INR",N3/80,N3)) -> 106.75 | S3: =IF(OR(Q3="",R3="",Q3=0),"",(R3-Q3)/Q3) -> 9.0470588 | T3: =IF(OR(E3="",E3=0),"Not Rated",IF(E3>=8,"Must Watch",IF(E3>=6,"Worth a watch","Skip"))) -> Must Watch
A4: 109 | B4: Kabhi Khushi Kabhie Gham | C4: Bollywood | D4: 2001 | E4: 7.4 | F4: Dharma Productions | G4: 1 | H4: 390 | I4: 1360 | J4: Millions | K4: INR | L4: =IF(J4="","",IF(J4="Billions",1000,1)) -> 1 | M4: =IF(H4="","",H4*L4) -> 390 | N4: =IF(I4="","",I4*L4) -> 1360 | O4: =IF(M4="","",IF(K4="INR",M4,M4*80)) -> 390 | P4: =IF(N4="","",IF(K4="INR",N4,N4*80)) -> 1360 | Q4: =IF(M4="","",IF(K4="INR",M4/80,M4)) -> 4.875 | R4: =IF(N4="","",IF(K4="INR",N4/80,N4)) -> 17 | S4: =IF(OR(Q4="",R4="",Q4=0),"",(R4-Q4)/Q4) -> 2.4871795 | T4: =IF(OR(E4="",E4=0),"Not Rated",IF(E4>=8,"Must Watch",IF(E4>=6,"Worth a watch","Skip"))) -> Worth a watch
A5: 129 | B5: Munna Bhai M.B.B.S. | C5: Bollywood | D5: 2003 | E5: 8.1 | F5: Vinod Chopra Productions | G5: 1 | H5: 100 | I5: 410 | J5: Millions | K5: INR | L5: =IF(J5="","",IF(J5="Billions",1000,1)) -> 1 | M5: =IF(H5="","",H5*L5) -> 100 | N5: =IF(I5="","",I5*L5) -> 410 | O5: =IF(M5="","",IF(K5="INR",M5,M5*80)) -> 100 | P5: =IF(N5="","",IF(K5="INR",N5,N5*80)) -> 410 | Q5: =IF(M5="","",IF(K5="INR",M5/80,M5)) -> 1.25 | R5: =IF(N5="","",IF(K5="INR",N5/80,N5)) -> 5.125 | S5: =IF(OR(Q5="",R5="",Q5=0),"",(R5-Q5)/Q5) -> 3.1 | T5: =IF(OR(E5="",E5=0),"Not Rated",IF(E5>=8,"Must Watch",IF(E5>=6,"Worth a watch","Skip"))) -> Must Watch
A6: 131 | B6: Sanju | C6: Bollywood | D6: 2018 | E6: 0 | F6: Vinod Chopra Films | G6: 1 | H6: 1 | I6: 5.9 | J6: Billions | K6: INR | L6: =IF(J6="","",IF(J6="Billions",1000,1)) -> 1000 | M6: =IF(H6="","",H6*L6) -> 1000 | N6: =IF(I6="","",I6*L6) -> 5900 | O6: =IF(M6="","",IF(K6="INR",M6,M6*80)) -> 1000 | P6: =IF(N6="","",IF(K6="INR",N6,N6*80)) -> 5900 | Q6: =IF(M6="","",IF(K6="INR",M6/80,M6)) -> 12.5 | R6: =IF(N6="","",IF(K6="INR",N6/80,N6)) -> 73.75 | S6: =IF(OR(Q6="",R6="",Q6=0),"",(R6-Q6)/Q6) -> 4.9 | T6: =IF(OR(E6="",E6=0),"Not Rated",IF(E6>=8,"Must Watch",IF(E6>=6,"Worth a watch","Skip"))) -> Not Rated
A7: 135 | B7: The Kashmir Files | C7: Bollywood | D7: 2022 | E7: 8.3 | F7: Zee Studios | G7: 1 | H7: 250 | I7: 3409 | J7: Millions | K7: INR | L7: =IF(J7="","",IF(J7="Billions",1000,1)) -> 1 | M7: =IF(H7="","",H7*L7) -> 250 | N7: =IF(I7="","",I7*L7) -> 3409 | O7: =IF(M7="","",IF(K7="INR",M7,M7*80)) -> 250 | P7: =IF(N7="","",IF(K7="INR",N7,N7*80)) -> 3409 | Q7: =IF(M7="","",IF(K7="INR",M7/80,M7)) -> 3.125 | R7: =IF(N7="","",IF(K7="INR",N7/80,N7)) -> 42.6125 | S7: =IF(OR(Q7="",R7="",Q7=0),"",(R7-Q7)/Q7) -> 12.636 | T7: =IF(OR(E7="",E7=0),"Not Rated",IF(E7>=8,"Must Watch",IF(E7>=6,"Worth a watch","Skip"))) -> Must Watch
A8: 136 | B8: Bajrangi Bhaijaan | C8: Bollywood | D8: 2015 | E8: 8.1 | F8: Salman Khan Films | G8: 1 | H8: 900 | I8: 11690 | J8: Millions | K8: INR | L8: =IF(J8="","",IF(J8="Billions",1000,1)) -> 1 | M8: =IF(H8="","",H8*L8) -> 900 | N8: =IF(I8="","",I8*L8) -> 11690 | O8: =IF(M8="","",IF(K8="INR",M8,M8*80)) -> 900 | P8: =IF(N8="","",IF(K8="INR",N8,N8*80)) -> 11690 | Q8: =IF(M8="","",IF(K8="INR",M8/80,M8)) -> 11.25 | R8: =IF(N8="","",IF(K8="INR",N8/80,N8)) -> 146.125 | S8: =IF(OR(Q8="",R8="",Q8=0),"",(R8-Q8)/Q8) -> 11.988889 | T8: =IF(OR(E8="",E8=0),"Not Rated",IF(E8>=8,"Must Watch",IF(E8>=6,"Worth a watch","Skip"))) -> Must Watch
A9: 140 | B9: Shershaah | C9: Bollywood | D9: 2021 | E9: 8.4 | F9: Dharma Productions | G9: 1 | H9: 500 | I9: 950 | J9: Millions | K9: INR | L9: =IF(J9="","",IF(J9="Billions",1000,1)) -> 1 | M9: =IF(H9="","",H9*L9) -> 500 | N9: =IF(I9="","",I9*L9) -> 950 | O9: =IF(M9="","",IF(K9="INR",M9,M9*80)) -> 500 | P9: =IF(N9="","",IF(K9="INR",N9,N9*80)) -> 950 | Q9: =IF(M9="","",IF(K9="INR",M9/80,M9)) -> 6.25 | R9: =IF(N9="","",IF(K9="INR",N9/80,N9)) -> 11.875 | S9: =IF(OR(Q9="",R9="",Q9=0),"",(R9-Q9)/Q9) -> 0.9 | T9: =IF(OR(E9="",E9=0),"Not Rated",IF(E9>=8,"Must Watch",IF(E9>=6,"Worth a watch","Skip"))) -> Must Watch
A10: 106 | B10: Sholay | C10: Bollywood | D10: 1975 | E10: 8.1 | F10: United Producers | G10: 1 | L10: =IF(J10="","",IF(J10="Billions",1000,1)) | M10: =IF(H10="","",H10*L10) | N10: =IF(I10="","",I10*L10) | O10: =IF(M10="","",IF(K10="INR",M10,M10*80)) | P10: =IF(N10="","",IF(K10="INR",N10,N10*80)) | Q10: =IF(M10="","",IF(K10="INR",M10/80,M10)) | R10: =IF(N10="","",IF(K10="INR",N10/80,N10)) | S10: =IF(OR(Q10="",R10="",Q10=0),"",(R10-Q10)/Q10) | T10: =IF(OR(E10="",E10=0),"Not Rated",IF(E10>=8,"Must Watch",IF(E10>=6,"Worth a watch","Skip"))) -> Must Watch
A11: 110 | B11: Bajirao Mastani | C11: Bollywood | D11: 2015 | E11: 7.2 | F11: Not Available | G11: 1 | H11: 1.4 | I11: 3.5 | J11: Billions | K11: INR | L11: =IF(J11="","",IF(J11="Billions",1000,1)) -> 1000 | M11: =IF(H11="","",H11*L11) -> 1400 | N11: =IF(I11="","",I11*L11) -> 3500 | O11: =IF(M11="","",IF(K11="INR",M11,M11*80)) -> 1400 | P11: =IF(N11="","",IF(K11="INR",N11,N11*80)) -> 3500 | Q11: =IF(M11="","",IF(K11="INR",M11/80,M11)) -> 17.5 | R11: =IF(N11="","",IF(K11="INR",N11/80,N11)) -> 43.75 | S11: =IF(OR(Q11="",R11="",Q11=0),"",(R11-Q11)/Q11) -> 1.5 | T11: =IF(OR(E11="",E11=0),"Not Rated",IF(E11>=8,"Must Watch",IF(E11>=6,"Worth a watch","Skip"))) -> Worth a watch
A12: 108 | B12: 3 Idiots | C12: Bollywood | D12: 2009 | E12: 8.4 | F12: Vinod Chopra Films | G12: 1 | H12: 550 | I12: 4000 | J12: Millions | K12: INR | L12: =IF(J12="","",IF(J12="Billions",1000,1)) -> 1 | M12: =IF(H12="","",H12*L12) -> 550 | N12: =IF(I12="","",I12*L12) -> 4000 | O12: =IF(M12="","",IF(K12="INR",M12,M12*80)) -> 550 | P12: =IF(N12="","",IF(K12="INR",N12,N12*80)) -> 4000 | Q12: =IF(M12="","",IF(K12="INR",M12/80,M12)) -> 6.875 | R12: =IF(N12="","",IF(K12="INR",N12/80,N12)) -> 50 | S12: =IF(OR(Q12="",R12="",Q12=0),"",(R12-Q12)/Q12) -> 6.2727273 | T12: =IF(OR(E12="",E12=0),"Not Rated",IF(E12>=8,"Must Watch",IF(E12>=6,"Worth a watch","Skip"))) -> Must Watch
A13: 107 | B13: Dilwale Dulhania Le Jayenge | C13: Bollywood | D13: 1995 | E13: 8 | F13: Yash Raj Films | G13: 1 | H13: 400 | I13: 2000 | J13: Millions | K13: INR | L13: =IF(J13="","",IF(J13="Billions",1000,1)) -> 1 | M13: =IF(H13="","",H13*L13) -> 400 | N13: =IF(I13="","",I13*L13) -> 2000 | O13: =IF(M13="","",IF(K13="INR",M13,M13*80)) -> 400 | P13: =IF(N13="","",IF(K13="INR",N13,N13*80)) -> 2000 | Q13: =IF(M13="","",IF(K13="INR",M13/80,M13)) -> 5 | R13: =IF(N13="","",IF(K13="INR",N13/80,N13)) -> 25 | S13: =IF(OR(Q13="",R13="",Q13=0),"",(R13-Q13)/Q13) -> 4 | T13: =IF(OR(E13="",E13=0),"Not Rated",IF(E13>=8,"Must Watch",IF(E13>=6,"Worth a watch","Skip"))) -> Must Watch
A14: 139 | B14: Race 3 | C14: Bollywood | D14: 2018 | E14: 1.9 | F14: Salman Khan Films | G14: 1 | H14: 1.8 | I14: 3.1 | J14: Billions | K14: INR | L14: =IF(J14="","",IF(J14="Billions",1000,1)) -> 1000 | M14: =IF(H14="","",H14*L14) -> 1800 | N14: =IF(I14="","",I14*L14) -> 3100 | O14: =IF(M14="","",IF(K14="INR",M14,M14*80)) -> 1800 | P14: =IF(N14="","",IF(K14="INR",N14,N14*80)) -> 3100 | Q14: =IF(M14="","",IF(K14="INR",M14/80,M14)) -> 22.5 | R14: =IF(N14="","",IF(K14="INR",N14/80,N14)) -> 38.75 | S14: =IF(OR(Q14="",R14="",Q14=0),"",(R14-Q14)/Q14) -> 0.72222222 | T14: =IF(OR(E14="",E14=0),"Not Rated",IF(E14>=8,"Must Watch",IF(E14>=6,"Worth a watch","Skip"))) -> Skip
A15: 132 | B15: Pushpa: The Rise - Part 1 | C15: Bollywood | D15: 2021 | E15: 7.6 | F15: Mythri Movie Makers | G15: 2 | H15: 2 | I15: 3.6 | J15: Billions | K15: INR | L15: =IF(J15="","",IF(J15="Billions",1000,1)) -> 1000 | M15: =IF(H15="","",H15*L15) -> 2000 | N15: =IF(I15="","",I15*L15) -> 3600 | O15: =IF(M15="","",IF(K15="INR",M15,M15*80)) -> 2000 | P15: =IF(N15="","",IF(K15="INR",N15,N15*80)) -> 3600 | Q15: =IF(M15="","",IF(K15="INR",M15/80,M15)) -> 25 | R15: =IF(N15="","",IF(K15="INR",N15/80,N15)) -> 45 | S15: =IF(OR(Q15="",R15="",Q15=0),"",(R15-Q15)/Q15) -> 0.8 | T15: =IF(OR(E15="",E15=0),"Not Rated",IF(E15>=8,"Must Watch",IF(E15>=6,"Worth a watch","Skip"))) -> Worth a watch
A16: 133 | B16: RRR | C16: Bollywood | D16: 2022 | E16: 8 | F16: DVV Entertainment | G16: 2 | H16: 5.5 | I16: 12 | J16: Billions | K16: INR | L16: =IF(J16="","",IF(J16="Billions",1000,1)) -> 1000 | M16: =IF(H16="","",H16*L16) -> 5500 | N16: =IF(I16="","",I16*L16) -> 12000 | O16: =IF(M16="","",IF(K16="INR",M16,M16*80)) -> 5500 | P16: =IF(N16="","",IF(K16="INR",N16,N16*80)) -> 12000 | Q16: =IF(M16="","",IF(K16="INR",M16/80,M16)) -> 68.75 | R16: =IF(N16="","",IF(K16="INR",N16/80,N16)) -> 150 | S16: =IF(OR(Q16="",R16="",Q16=0),"",(R16-Q16)/Q16) -> 1.1818182 | T16: =IF(OR(E16="",E16=0),"Not Rated",IF(E16>=8,"Must Watch",IF(E16>=6,"Worth a watch","Skip"))) -> Must Watch
A17: 134 | B17: Baahubali: The Beginning | C17: Bollywood | D17: 2015 | E17: 8 | F17: Arka Media Works | G17: 2 | H17: 1.8 | I17: 6.5 | J17: Billions | K17: INR | L17: =IF(J17="","",IF(J17="Billions",1000,1)) -> 1000 | M17: =IF(H17="","",H17*L17) -> 1800 | N17: =IF(I17="","",I17*L17) -> 6500 | O17: =IF(M17="","",IF(K17="INR",M17,M17*80)) -> 1800 | P17: =IF(N17="","",IF(K17="INR",N17,N17*80)) -> 6500 | Q17: =IF(M17="","",IF(K17="INR",M17/80,M17)) -> 22.5 | R17: =IF(N17="","",IF(K17="INR",N17/80,N17)) -> 81.25 | S17: =IF(OR(Q17="",R17="",Q17=0),"",(R17-Q17)/Q17) -> 2.6111111 | T17: =IF(OR(E17="",E17=0),"Not Rated",IF(E17>=8,"Must Watch",IF(E17>=6,"Worth a watch","Skip"))) -> Must Watch
A18: 101 | B18: K.G.F: Chapter 2 | C18: Bollywood | D18: 2022 | E18: 8.4 | F18: Hombale Films | G18: 3 | H18: 1 | I18: 12.5 | J18: Billions | K18: INR | L18: =IF(J18="","",IF(J18="Billions",1000,1)) -> 1000 | M18: =IF(H18="","",H18*L18) -> 1000 | N18: =IF(I18="","",I18*L18) -> 12500 | O18: =IF(M18="","",IF(K18="INR",M18,M18*80)) -> 1000 | P18: =IF(N18="","",IF(K18="INR",N18,N18*80)) -> 12500 | Q18: =IF(M18="","",IF(K18="INR",M18/80,M18)) -> 12.5 | R18: =IF(N18="","",IF(K18="INR",N18/80,N18)) -> 156.25 | S18: =IF(OR(Q18="",R18="",Q18=0),"",(R18-Q18)/Q18) -> 11.5 | T18: =IF(OR(E18="",E18=0),"Not Rated",IF(E18>=8,"Must Watch",IF(E18>=6,"Worth a watch","Skip"))) -> Must Watch
A19: 126 | B19: Avengers: Infinity War | C19: Hollywood | D19: 2018 | E19: 8.4 | F19: Marvel Studios | G19: 5 | H19: 400 | I19: 2048 | J19: Millions | K19: USD | L19: =IF(J19="","",IF(J19="Billions",1000,1)) -> 1 | M19: =IF(H19="","",H19*L19) -> 400 | N19: =IF(I19="","",I19*L19) -> 2048 | O19: =IF(M19="","",IF(K19="INR",M19,M19*80)) -> 32000 | P19: =IF(N19="","",IF(K19="INR",N19,N19*80)) -> 163840 | Q19: =IF(M19="","",IF(K19="INR",M19/80,M19)) -> 400 | R19: =IF(N19="","",IF(K19="INR",N19/80,N19)) -> 2048 | S19: =IF(OR(Q19="",R19="",Q19=0),"",(R19-Q19)/Q19) -> 4.12 | T19: =IF(OR(E19="",E19=0),"Not Rated",IF(E19>=8,"Must Watch",IF(E19>=6,"Worth a watch","Skip"))) -> Must Watch
A20: 112 | B20: Inception | C20: Hollywood | D20: 2010 | E20: 8.8 | F20: Warner Bros. Pictures | G20: 5 | L20: =IF(J20="","",IF(J20="Billions",1000,1)) | M20: =IF(H20="","",H20*L20) | N20: =IF(I20="","",I20*L20) | O20: =IF(M20="","",IF(K20="INR",M20,M20*80)) | P20: =IF(N20="","",IF(K20="INR",N20,N20*80)) | Q20: =IF(M20="","",IF(K20="INR",M20/80,M20)) | R20: =IF(N20="","",IF(K20="INR",N20/80,N20)) | S20: =IF(OR(Q20="",R20="",Q20=0),"",(R20-Q20)/Q20) | T20: =IF(OR(E20="",E20=0),"Not Rated",IF(E20>=8,"Must Watch",IF(E20>=6,"Worth a watch","Skip"))) -> Must Watch
A21: 138 | B21: Captain America: The Winter Soldier | C21: Hollywood | D21: 2014 | E21: 7.8 | F21: Marvel Studios | G21: 5 | H21: 177 | I21: 714.4 | J21: Millions | K21: USD | L21: =IF(J21="","",IF(J21="Billions",1000,1)) -> 1 | M21: =IF(H21="","",H21*L21) -> 177 | N21: =IF(I21="","",I21*L21) -> 714.4 | O21: =IF(M21="","",IF(K21="INR",M21,M21*80)) -> 14160 | P21: =IF(N21="","",IF(K21="INR",N21,N21*80)) -> 57152 | Q21: =IF(M21="","",IF(K21="INR",M21/80,M21)) -> 177 | R21: =IF(N21="","",IF(K21="INR",N21/80,N21)) -> 714.4 | S21: =IF(OR(Q21="",R21="",Q21=0),"",(R21-Q21)/Q21) -> 3.0361582 | T21: =IF(OR(E21="",E21=0),"Not Rated",IF(E21>=8,"Must Watch",IF(E21>=6,"Worth a watch","Skip"))) -> Worth a watch
A22: 137 | B22: Captain America: The First Avenger | C22: Hollywood | D22: 2011 | E22: 6.9 | F22: Marvel Studios | G22: 5 | H22: 216.7 | I22: 370.6 | J22: Millions | K22: USD | L22: =IF(J22="","",IF(J22="Billions",1000,1)) -> 1 | M22: =IF(H22="","",H22*L22) -> 216.7 | N22: =IF(I22="","",I22*L22) -> 370.6 | O22: =IF(M22="","",IF(K22="INR",M22,M22*80)) -> 17336 | P22: =IF(N22="","",IF(K22="INR",N22,N22*80)) -> 29648 | Q22: =IF(M22="","",IF(K22="INR",M22/80,M22)) -> 216.7 | R22: =IF(N22="","",IF(K22="INR",N22/80,N22)) -> 370.6 | S22: =IF(OR(Q22="",R22="",Q22=0),"",(R22-Q22)/Q22) -> 0.71019843 | T22: =IF(OR(E22="",E22=0),"Not Rated",IF(E22>=8,"Must Watch",IF(E22>=6,"Worth a watch","Skip"))) -> Worth a watch
A23: 125 | B23: Avengers: Endgame | C23: Hollywood | D23: 2019 | E23: 8.4 | F23: Marvel Studios | G23: 5 | H23: 400 | I23: 2798 | J23: Millions | K23: USD | L23: =IF(J23="","",IF(J23="Billions",1000,1)) -> 1 | M23: =IF(H23="","",H23*L23) -> 400 | N23: =IF(I23="","",I23*L23) -> 2798 | O23: =IF(M23="","",IF(K23="INR",M23,M23*80)) -> 32000 | P23: =IF(N23="","",IF(K23="INR",N23,N23*80)) -> 223840 | Q23: =IF(M23="","",IF(K23="INR",M23/80,M23)) -> 400 | R23: =IF(N23="","",IF(K23="INR",N23/80,N23)) -> 2798 | S23: =IF(OR(Q23="",R23="",Q23=0),"",(R23-Q23)/Q23) -> 5.995 | T23: =IF(OR(E23="",E23=0),"Not Rated",IF(E23>=8,"Must Watch",IF(E23>=6,"Worth a watch","Skip"))) -> Must Watch
A24: 113 | B24: Interstellar | C24: Hollywood | D24: 2014 | E24: 8.6 | F24: Warner Bros. Pictures | G24: 5 | H24: 165 | I24: 701.8 | J24: Millions | K24: USD | L24: =IF(J24="","",IF(J24="Billions",1000,1)) -> 1 | M24: =IF(H24="","",H24*L24) -> 165 | N24: =IF(I24="","",I24*L24) -> 701.8 | O24: =IF(M24="","",IF(K24="INR",M24,M24*80)) -> 13200 | P24: =IF(N24="","",IF(K24="INR",N24,N24*80)) -> 56144 | Q24: =IF(M24="","",IF(K24="INR",M24/80,M24)) -> 165 | R24: =IF(N24="","",IF(K24="INR",N24/80,N24)) -> 701.8 | S24: =IF(OR(Q24="",R24="",Q24=0),"",(R24-Q24)/Q24) -> 3.2533333 | T24: =IF(OR(E24="",E24=0),"Not Rated",IF(E24>=8,"Must Watch",IF(E24>=6,"Worth a watch","Skip"))) -> Must Watch
A25: 111 | B25: The Shawshank Redemption | C25: Hollywood | D25: 1994 | E25: 9.3 | F25: Castle Rock Entertainment | G25: 5 | H25: 25 | I25: 73.3 | J25: Millions | K25: USD | L25: =IF(J25="","",IF(J25="Billions",1000,1)) -> 1 | M25: =IF(H25="","",H25*L25) -> 25 | N25: =IF(I25="","",I25*L25) -> 73.3 | O25: =IF(M25="","",IF(K25="INR",M25,M25*80)) -> 2000 | P25: =IF(N25="","",IF(K25="INR",N25,N25*80)) -> 5864 | Q25: =IF(M25="","",IF(K25="INR",M25/80,M25)) -> 25 | R25: =IF(N25="","",IF(K25="INR",N25/80,N25)) -> 73.3 | S25: =IF(OR(Q25="",R25="",Q25=0),"",(R25-Q25)/Q25) -> 1.932 | T25: =IF(OR(E25="",E25=0),"Not Rated",IF(E25>=8,"Must Watch",IF(E25>=6,"Worth a watch","Skip"))) -> Must Watch
A26: 116 | B26: Gladiator | C26: Hollywood | D26: 2000 | E26: 8.5 | F26: Universal Pictures | G26: 5 | H26: 103 | I26: 460.5 | J26: Millions | K26: USD | L26: =IF(J26="","",IF(J26="Billions",1000,1)) -> 1 | M26: =IF(H26="","",H26*L26) -> 103 | N26: =IF(I26="","",I26*L26) -> 460.5 | O26: =IF(M26="","",IF(K26="INR",M26,M26*80)) -> 8240 | P26: =IF(N26="","",IF(K26="INR",N26,N26*80)) -> 36840 | Q26: =IF(M26="","",IF(K26="INR",M26/80,M26)) -> 103 | R26: =IF(N26="","",IF(K26="INR",N26/80,N26)) -> 460.5 | S26: =IF(OR(Q26="",R26="",Q26=0),"",(R26-Q26)/Q26) -> 3.4708738 | T26: =IF(OR(E26="",E26=0),"Not Rated",IF(E26>=8,"Must Watch",IF(E26>=6,"Worth a watch","Skip"))) -> Must Watch
A27: 115 | B27: The Pursuit of Happyness | C27: Hollywood | D27: 2006 | E27: 8 | F27: Columbia Pictures | G27: 5 | H27: 55 | I27: 307.1 | J27: Millions | K27: USD | L27: =IF(J27="","",IF(J27="Billions",1000,1)) -> 1 | M27: =IF(H27="","",H27*L27) -> 55 | N27: =IF(I27="","",I27*L27) -> 307.1 | O27: =IF(M27="","",IF(K27="INR",M27,M27*80)) -> 4400 | P27: =IF(N27="","",IF(K27="INR",N27,N27*80)) -> 24568 | Q27: =IF(M27="","",IF(K27="INR",M27/80,M27)) -> 55 | R27: =IF(N27="","",IF(K27="INR",N27/80,N27)) -> 307.1 | S27: =IF(OR(Q27="",R27="",Q27=0),"",(R27-Q27)/Q27) -> 4.5836364 | T27: =IF(OR(E27="",E27=0),"Not Rated",IF(E27>=8,"Must Watch",IF(E27>=6,"Worth a watch","Skip"))) -> Must Watch
A28: 103 | B28: Thor: The Dark World | C28: Hollywood | D28: 2013 | E28: 6.8 | F28: Marvel Studios | G28: 5 | H28: 165 | I28: 644.8 | J28: Millions | K28: USD | L28: =IF(J28="","",IF(J28="Billions",1000,1)) -> 1 | M28: =IF(H28="","",H28*L28) -> 165 | N28: =IF(I28="","",I28*L28) -> 644.8 | O28: =IF(M28="","",IF(K28="INR",M28,M28*80)) -> 13200 | P28: =IF(N28="","",IF(K28="INR",N28,N28*80)) -> 51584 | Q28: =IF(M28="","",IF(K28="INR",M28/80,M28)) -> 165 | R28: =IF(N28="","",IF(K28="INR",N28/80,N28)) -> 644.8 | S28: =IF(OR(Q28="",R28="",Q28=0),"",(R28-Q28)/Q28) -> 2.9078788 | T28: =IF(OR(E28="",E28=0),"Not Rated",IF(E28>=8,"Must Watch",IF(E28>=6,"Worth a watch","Skip"))) -> Worth a watch
A29: 102 | B29: Doctor Strange in the Multiverse of Madness | C29: Hollywood | D29: 2022 | E29: 7 | F29: Marvel Studios | G29: 5 | H29: 200 | I29: 954.8 | J29: Millions | K29: USD | L29: =IF(J29="","",IF(J29="Billions",1000,1)) -> 1 | M29: =IF(H29="","",H29*L29) -> 200 | N29: =IF(I29="","",I29*L29) -> 954.8 | O29: =IF(M29="","",IF(K29="INR",M29,M29*80)) -> 16000 | P29: =IF(N29="","",IF(K29="INR",N29,N29*80)) -> 76384 | Q29: =IF(M29="","",IF(K29="INR",M29/80,M29)) -> 200 | R29: =IF(N29="","",IF(K29="INR",N29/80,N29)) -> 954.8 | S29: =IF(OR(Q29="",R29="",Q29=0),"",(R29-Q29)/Q29) -> 3.774 | T29: =IF(OR(E29="",E29=0),"Not Rated",IF(E29>=8,"Must Watch",IF(E29>=6,"Worth a watch","Skip"))) -> Worth a watch
A30: 105 | B30: Thor: Love and Thunder | C30: Hollywood | D30: 2022 | E30: 6.8 | F30: Marvel Studios | G30: 5 | H30: 250 | I30: 670 | J30: Millions | K30: USD | L30: =IF(J30="","",IF(J30="Billions",1000,1)) -> 1 | M30: =IF(H30="","",H30*L30) -> 250 | N30: =IF(I30="","",I30*L30) -> 670 | O30: =IF(M30="","",IF(K30="INR",M30,M30*80)) -> 20000 | P30: =IF(N30="","",IF(K30="INR",N30,N30*80)) -> 53600 | Q30: =IF(M30="","",IF(K30="INR",M30/80,M30)) -> 250 | R30: =IF(N30="","",IF(K30="INR",N30/80,N30)) -> 670 | S30: =IF(OR(Q30="",R30="",Q30=0),"",(R30-Q30)/Q30) -> 1.68 | T30: =IF(OR(E30="",E30=0),"Not Rated",IF(E30>=8,"Must Watch",IF(E30>=6,"Worth a watch","Skip"))) -> Worth a watch
A31: 104 | B31: Thor: Ragnarok | C31: Hollywood | D31: 2017 | E31: 7.9 | F31: Marvel Studios | G31: 5 | H31: 180 | I31: 854 | J31: Millions | K31: USD | L31: =IF(J31="","",IF(J31="Billions",1000,1)) -> 1 | M31: =IF(H31="","",H31*L31) -> 180 | N31: =IF(I31="","",I31*L31) -> 854 | O31: =IF(M31="","",IF(K31="INR",M31,M31*80)) -> 14400 | P31: =IF(N31="","",IF(K31="INR",N31,N31*80)) -> 68320 | Q31: =IF(M31="","",IF(K31="INR",M31/80,M31)) -> 180 | R31: =IF(N31="","",IF(K31="INR",N31/80,N31)) -> 854 | S31: =IF(OR(Q31="",R31="",Q31=0),"",(R31-Q31)/Q31) -> 3.7444444 | T31: =IF(OR(E31="",E31=0),"Not Rated",IF(E31>=8,"Must Watch",IF(E31>=6,"Worth a watch","Skip"))) -> Worth a watch
A32: 117 | B32: Titanic | C32: Hollywood | D32: 1997 | E32: 7.9 | F32: Paramount Pictures | G32: 5 | H32: 200 | I32: 2202 | J32: Millions | K32: USD | L32: =IF(J32="","",IF(J32="Billions",1000,1)) -> 1 | M32: =IF(H32="","",H32*L32) -> 200 | N32: =IF(I32="","",I32*L32) -> 2202 | O32: =IF(M32="","",IF(K32="INR",M32,M32*80)) -> 16000 | P32: =IF(N32="","",IF(K32="INR",N32,N32*80)) -> 176160 | Q32: =IF(M32="","",IF(K32="INR",M32/80,M32)) -> 200 | R32: =IF(N32="","",IF(K32="INR",N32/80,N32)) -> 2202 | S32: =IF(OR(Q32="",R32="",Q32=0),"",(R32-Q32)/Q32) -> 10.01 | T32: =IF(OR(E32="",E32=0),"Not Rated",IF(E32>=8,"Must Watch",IF(E32>=6,"Worth a watch","Skip"))) -> Worth a watch
... A35: 124 | B35: Parasite | C35: Hollywood | D35: 2019 | E35: 8.5 | F35: Not Available | G35: 5 | H35: 15.5 | I35: 263.1 | J35: Millions | K35: USD | L35: =IF(J35="","",IF(J35="Billions",1000,1)) -> 1 | M35: =IF(H35="","",H35*L35) -> 15.5 | N35: =IF(I35="","",I35*L35) -> 263.1 | O35: =IF(M35="","",IF(K35="INR",M35,M35*80)) -> 1240 | P35: =IF(N35="","",IF(K35="INR",N35,N35*80)) -> 21048 | Q35: =IF(M35="","",IF(K35="INR",M35/80,M35)) -> 15.5 | R35: =IF(N35="","",IF(K35="INR",N35/80,N35)) -> 263.1 | S35: =IF(OR(Q35="",R35="",Q35=0),"",(R35-Q35)/Q35) -> 15.974194 | T35: =IF(OR(E35="",E35=0),"Not Rated",IF(E35>=8,"Must Watch",IF(E35>=6,"Worth a watch","Skip"))) -> Must Watch
A36: 121 | B36: The Dark Knight | C36: Hollywood | D36: 2008 | E36: 9 | F36: Syncopy | G36: 5 | H36: 185 | I36: 1006 | J36: Millions | K36: USD | L36: =IF(J36="","",IF(J36="Billions",1000,1)) -> 1 | M36: =IF(H36="","",H36*L36) -> 185 | N36: =IF(I36="","",I36*L36) -> 1006 | O36: =IF(M36="","",IF(K36="INR",M36,M36*80)) -> 14800 | P36: =IF(N36="","",IF(K36="INR",N36,N36*80)) -> 80480 | Q36: =IF(M36="","",IF(K36="INR",M36/80,M36)) -> 185 | R36: =IF(N36="","",IF(K36="INR",N36/80,N36)) -> 1006 | S36: =IF(OR(Q36="",R36="",Q36=0),"",(R36-Q36)/Q36) -> 4.4378378 | T36: =IF(OR(E36="",E36=0),"Not Rated",IF(E36>=8,"Must Watch",IF(E36>=6,"Worth a watch","Skip"))) -> Must Watch | W36: =(R39-Q39)/Q39 -> 39.416667
A37: 118 | B37: It's a Wonderful Life | C37: Hollywood | D37: 1946 | E37: 8.6 | F37: Liberty Films | G37: 5 | H37: 3.18 | I37: 3.3 | J37: Millions | K37: USD | L37: =IF(J37="","",IF(J37="Billions",1000,1)) -> 1 | M37: =IF(H37="","",H37*L37) -> 3.18 | N37: =IF(I37="","",I37*L37) -> 3.3 | O37: =IF(M37="","",IF(K37="INR",M37,M37*80)) -> 254.4 | P37: =IF(N37="","",IF(K37="INR",N37,N37*80)) -> 264 | Q37: =IF(M37="","",IF(K37="INR",M37/80,M37)) -> 3.18 | R37: =IF(N37="","",IF(K37="INR",N37/80,N37)) -> 3.3 | S37: =IF(OR(Q37="",R37="",Q37=0),"",(R37-Q37)/Q37) -> 0.037735849 | T37: =IF(OR(E37="",E37=0),"Not Rated",IF(E37>=8,"Must Watch",IF(E37>=6,"Worth a watch","Skip"))) -> Must Watch
A38: 119 | B38: Avatar | C38: Hollywood | D38: 2009 | E38: 7.8 | F38: 20th Century Fox | G38: 5 | H38: 237 | I38: 2847 | J38: Millions | K38: USD | L38: =IF(J38="","",IF(J38="Billions",1000,1)) -> 1 | M38: =IF(H38="","",H38*L38) -> 237 | N38: =IF(I38="","",I38*L38) -> 2847 | O38: =IF(M38="","",IF(K38="INR",M38,M38*80)) -> 18960 | P38: =IF(N38="","",IF(K38="INR",N38,N38*80)) -> 227760 | Q38: =IF(M38="","",IF(K38="INR",M38/80,M38)) -> 237 | R38: =IF(N38="","",IF(K38="INR",N38/80,N38)) -> 2847 | S38: =IF(OR(Q38="",R38="",Q38=0),"",(R38-Q38)/Q38) -> 11.012658 | T38: =IF(OR(E38="",E38=0),"Not Rated",IF(E38>=8,"Must Watch",IF(E38>=6,"Worth a watch","Skip"))) -> Worth a watch
A39: 120 | B39: The Godfather | C39: Hollywood | D39: 1972 | E39: 9.2 | F39: Paramount Pictures | G39: 5 | H39: 7.2 | I39: 291 | J39: Millions | K39: USD | L39: =IF(J39="","",IF(J39="Billions",1000,1)) -> 1 | M39: =IF(H39="","",H39*L39) -> 7.2 | N39: =IF(I39="","",I39*L39) -> 291 | O39: =IF(M39="","",IF(K39="INR",M39,M39*80)) -> 576 | P39: =IF(N39="","",IF(K39="INR",N39,N39*80)) -> 23280 | Q39: =IF(M39="","",IF(K39="INR",M39/80,M39)) -> 7.2 | R39: =IF(N39="","",IF(K39="INR",N39/80,N39)) -> 291 | S39: =IF(OR(Q39="",R39="",Q39=0),"",(R39-Q39)/Q39) -> 39.416667 | T39: =IF(OR(E39="",E39=0),"Not Rated",IF(E39>=8,"Must Watch",IF(E39>=6,"Worth a watch","Skip"))) -> Must Watch
A40: 127 | B40: Pather Panchali | C40: Bollywood | D40: 1955 | E40: 8.3 | F40: Government of West Bengal | G40: 7 | H40: 70 | I40: 100 | J40: Millions | K40: INR | L40: =IF(J40="","",IF(J40="Billions",1000,1)) -> 1 | M40: =IF(H40="","",H40*L40) -> 70 | N40: =IF(I40="","",I40*L40) -> 100 | O40: =IF(M40="","",IF(K40="INR",M40,M40*80)) -> 70 | P40: =IF(N40="","",IF(K40="INR",N40,N40*80)) -> 100 | Q40: =IF(M40="","",IF(K40="INR",M40/80,M40)) -> 0.875 | R40: =IF(N40="","",IF(K40="INR",N40/80,N40)) -> 1.25 | S40: =IF(OR(Q40="",R40="",Q40=0),"",(R40-Q40)/Q40) -> 0.42857143 | T40: =IF(OR(E40="",E40=0),"Not Rated",IF(E40>=8,"Must Watch",IF(E40>=6,"Worth a watch","Skip"))) -> Must Watch
A41: 141 | B41: Thugs of Hindostan | C41: Bollywood | D41: 2018 | E41: 4.1 | F41: Yash Raj Films | G41: 1 | H41: 3 | I41: 1.5 | J41: Billions | K41: INR | L41: =IF(J41="","",IF(J41="Billions",1000,1)) -> 1000 | M41: =IF(H41="","",H41*L41) -> 3000 | N41: =IF(I41="","",I41*L41) -> 1500 | O41: =IF(M41="","",IF(K41="INR",M41,M41*80)) -> 3000 | P41: =IF(N41="","",IF(K41="INR",N41,N41*80)) -> 1500 | Q41: =IF(M41="","",IF(K41="INR",M41/80,M41)) -> 37.5 | R41: =IF(N41="","",IF(K41="INR",N41/80,N41)) -> 18.75 | S41: =IF(OR(Q41="",R41="",Q41=0),"",(R41-Q41)/Q41) -> -0.5 | T41: =IF(OR(E41="",E41=0),"Not Rated",IF(E41>=8,"Must Watch",IF(E41>=6,"Worth a watch","Skip"))) -> Skip
A42: 142 | B42: Shamshera | C42: Bollywood | D42: 2022 | E42: 5.6 | F42: Yash Raj Films | G42: 1 | H42: 1.5 | I42: 0.65 | J42: Billions | K42: INR | L42: =IF(J42="","",IF(J42="Billions",1000,1)) -> 1000 | M42: =IF(H42="","",H42*L42) -> 1500 | N42: =IF(I42="","",I42*L42) -> 650 | O42: =IF(M42="","",IF(K42="INR",M42,M42*80)) -> 1500 | P42: =IF(N42="","",IF(K42="INR",N42,N42*80)) -> 650 | Q42: =IF(M42="","",IF(K42="INR",M42/80,M42)) -> 18.75 | R42: =IF(N42="","",IF(K42="INR",N42/80,N42)) -> 8.125 | S42: =IF(OR(Q42="",R42="",Q42=0),"",(R42-Q42)/Q42) -> -0.56666667 | T42: =IF(OR(E42="",E42=0),"Not Rated",IF(E42>=8,"Must Watch",IF(E42>=6,"Worth a watch","Skip"))) -> Skip
...

Sheet movies
A1: movie_id_title | B1: industry | C1: release_year | D1: imdb_rating | E1: studio | F1: language_id
A2: 101:K.G.F: Chapter 2 | B2: Bollywood | C2: 2022 | D2: 8.4 | E2: Hombale Films | F2: 3
A3: 102:Doctor Strange in the Multiverse of Madness | B3: Hollywood | C3: 2022 | D3: 7 | E3: Marvel Studios | F3: 5
A4: 103:Thor: The Dark World | B4: Hollywood | C4: 2013 | D4: 6.8 | E4: Marvel Studios | F4: 5
A5: 104:Thor: Ragnarok | B5: Hollywood | C5: 2017 | D5: 7.9 | E5: Marvel Studios | F5: 5
A6: 105:Thor: Love and Thunder | B6: Hollywood | C6: 2022 | D6: 6.8 | E6: Marvel Studios | F6: 5
A7: 106:Sholay | B7: Bollywood | C7: 1975 | D7: 8.1 | E7: United Producers | F7: 1
A8: 107:Dilwale Dulhania Le Jayenge | B8: Bollywood | C8: 1995 | D8: 8 | E8: Yash Raj Films | F8: 1
A9: 108:3 Idiots | B9: Bollywood | C9: 2009 | D9: 8.4 | E9: Vinod Chopra Films | F9: 1
A10: 109:Kabhi Khushi Kabhie Gham | B10: Bollywood | C10: 2001 | D10: 7.4 | E10: Dharma Productions | F10: 1
A11: 110:Bajirao Mastani | B11: Bollywood | C11: 2015 | D11: 7.2 | F11: 1
A12: 111:The Shawshank Redemption | B12: Hollywood | C12: 1994 | D12: 9.3 | E12: Castle Rock Entertainment | F12: 5
A13: 112:Inception | B13: Hollywood | C13: 2010 | D13: 8.8 | E13: Warner Bros. Pictures | F13: 5
A14: 113:Interstellar | B14: Hollywood | C14: 2014 | D14: 8.6 | E14: Warner Bros. Pictures | F14: 5
A15: 115:The Pursuit of Happyness | B15: Hollywood | C15: 2006 | D15: 8 | E15: Columbia Pictures | F15: 5
A16: 116:Gladiator | B16: Hollywood | C16: 2000 | D16: 8.5 | E16: Universal Pictures | F16: 5
A17: 117:Titanic | B17: Hollywood | C17: 1997 | D17: 7.9 | E17: Paramount Pictures | F17: 5
A18: 118:It's a Wonderful Life | B18: Hollywood | C18: 1946 | D18: 8.6 | E18: Liberty Films | F18: 5
A19: 119:Avatar | B19: Hollywood | C19: 2009 | D19: 7.8 | E19: 20th Century Fox | F19: 5
A20: 120:The Godfather | B20: Hollywood | C20: 1972 | D20: 9.2 | E20: Paramount Pictures | F20: 5
A21: 121:The Dark Knight | B21: Hollywood | C21: 2008 | D21: 9 | E21: Syncopy | F21: 5
A22: 122:Schindler's List | B22: Hollywood | C22: 1993 | D22: 9 | E22: Universal Pictures | F22: 5
A23: 123:Jurassic Park | B23: Hollywood | C23: 1993 | D23: 8.2 | E23: Universal Pictures | F23: 5
A24: 124:Parasite | B24: Hollywood | C24: 2019 | D24: 8.5 | F24: 5
A25: 125:Avengers: Endgame | B25: Hollywood | C25: 2019 | D25: 8.4 | E25: Marvel Studios | F25: 5
A26: 126:Avengers: Infinity War | B26: Hollywood | C26: 2018 | D26: 8.4 | E26: Marvel Studios | F26: 5
A27: 127:Pather Panchali | B27: Bollywood | C27: 1955 | D27: 8.3 | E27: Government of West Bengal | F27: 7
A28: 128:Taare Zameen Par | B28: Bollywood | C28: 2007 | D28: 8.3 | F28: 1
A29: 129:Munna Bhai M.B.B.S. | B29: Bollywood | C29: 2003 | D29: 8.1 | E29: Vinod Chopra Productions | F29: 1
A30: 130:PK | B30: Bollywood | C30: 2014 | D30: 8.1 | E30: Vinod Chopra Films | F30: 1
A31: 131:Sanju | B31: Bollywood | C31: 2018 | D31: 0 | E31: Vinod Chopra Films | F31: 1
A32: 132:Pushpa: The Rise - Part 1 | B32: Bollywood | C32: 2021 | D32: 7.6 | E32: Mythri Movie Makers | F32: 2
A33: 133:RRR | B33: Bollywood | C33: 2022 | D33: 8 | E33: DVV Entertainment | F33: 2
A34: 134:Baahubali: The Beginning | B34: Bollywood | C34: 2015 | D34: 8 | E34: Arka Media Works | F34: 2
A35: 135:The Kashmir Files | B35: Bollywood | C35: 2022 | D35: 8.3 | E35: Zee Studios | F35: 1
A36: 136:Bajrangi Bhaijaan | B36: Bollywood | C36: 2015 | D36: 8.1 | E36: Salman Khan Films | F36: 1
A37: 137:Captain America: The First Avenger | B37: Hollywood | C37: 2011 | D37: 6.9 | E37: Marvel Studios | F37: 5
A38: 138:Captain America: The Winter Soldier | B38: Hollywood | C38: 2014 | D38: 7.8 | E38: Marvel Studios | F38: 5
A39: 139:Race 3 | B39: Bollywood | C39: 2018 | D39: 1.9 | E39: Salman Khan Films | F39: 1
A40: 140:Shershaah | B40: Bollywood | C40: 2021 | D40: 8.4 | E40: Dharma Productions | F40: 1
...

Sheet Notes
A1: Step | B1: What to do | C1: Where to check | E1: Calculation | F1: Plain-English formula | G1: What it means
A2: 1 | B2: Understand how the movie, financial, and language sheets connect. | C2: MovieFinancials!A1:R44 | E2: Unit Factor | F2: Millions = 1; Billions = 1,000 | G2: Converts the original amount into millions.
A3: 2 | B3: Treat movie details and original budget and revenue fields as entered data. | C3: MovieFinancials!A1:K44 | E3: Budget (Millions) | F3: Budget × Unit Factor | G3: Changes the budget into millions.
A4: 3 | B4: Treat the conversion columns as calculated results. | C4: MovieFinancials!L1:R44 | E4: Revenue (Millions) | F4: Revenue × Unit Factor | G4: Changes the revenue into millions.
A5: 4 | B5: Convert the budget to millions using the unit factor. | C5: MovieFinancials!H1:M44 | E5: Budget (INR mm) | F5: INR: same amount; USD: amount × 80 | G5: Shows budget in Indian rupees, in millions.
A6: 5 | B6: Convert INR amounts to USD by dividing by 80; leave USD amounts unchanged. | C6: MovieFinancials!K1:Q44 | E6: Revenue (INR mm) | F6: INR: same amount; USD: amount × 80 | G6: Shows revenue in Indian rupees, in millions.
A7: 6 | B7: Use ₹80 for every $1 in this dataset. | C7: MovieFinancials!K1:Q44 | E7: Budget (USD mm) | F7: USD: same amount; INR: amount ÷ 80 | G7: Shows budget in US dollars, in millions.
A8: 7 | B8: Check that the converted budget values match the calculation. | C8: MovieFinancials!H2:Q44 | E8: Revenue (USD mm) | F8: USD: same amount; INR: amount ÷ 80 | G8: Shows revenue in US dollars, in millions.
A9: 8 | B9: Note that the calculated results are currently typed in, not formula-driven. | C9: MovieFinancials!L1:R44
A10: 9 | B10: Later, replace the typed results with formulas so they update automatically. | C10: MovieFinancials!H1:R44 | E10: Why are there commas and quotation marks? | F10: They are Excel grammar, not extra business rules. | G10: Quotation marks show that Millions, Billions, and INR are words. Commas separate the choices Excel must make. The shorter formulas now use fewer instructions.
A11: 10 | B11: Fix the missing movie ID for Taare Zameen Par; it should be 128. | C11: MovieFinancials!A2:B2; movies!A28:F28 | E11: Simplified formula logic | F11: Budget in INR = Budget in millions; Budget in USD = Budget in millions ÷ 80. | G11: The formulas use the currency to choose the correct conversion automatically.
A12: 11 | B12: Investigate the missing financial data for Sholay. | C12: MovieFinancials!A10:R10 | E12: Important note | F12: The formulas must still use Excel syntax to work. | G12: A common reader can follow the plain-English formulas here without reading the technical Excel code.
A13: 12 | B13: Investigate the missing financial data for Inception. | C13: MovieFinancials!A20:R20
A14: 13 | B14: Use one consistent label for missing values instead of mixing blanks, NULL, and Not Available. | C14: MovieFinancials!E6:F6; MovieFinancials!F2:F35
A15: 14 | B15: Review the duplicate Thor: Love and Thunder record. | C15: movies!A6:F6; movies!A31:F31
A16: 15 | B16: Review the duplicate Parasite record. | C16: movies!A24:F24; movies!A30:F30
A17: 16 | B17: Check financial records for movie IDs 114, 406, and 412 because their movie records are missing. | C17: financials!A1:E45
A18: 17 | B18: Fix the movie ID 128 mismatch between the movie and combined sheets. | C18: movies!A28:F28; MovieFinancials!A1:R44
A19: 18 | B19: Check movie IDs 106 and 112 because their financial details are missing. | C19: MovieFinancials!A10:R20
A20: 19 | B20: Confirm that the unused Column1 field has been removed from the movies sheet. | C20: movies!G1:G46
A21: 20 | B21: Remove extra spaces from movie titles and studio names. | C21: movies!A4:E9
A22: 21 | B22: Check that every financial movie ID matches a movie record. | C22: movies!A1:F46; financials!A1:E45; MovieFinancials!A1:R44
A23: 22 | B23: Check that movies with expected financial data have matching financial records. | C23: movies!A1:F46; financials!A1:E45
A24: 23 | B24: Allow only Millions or Billions as valid units. | C24: financials!D1:D45
... A26: 25 | B26: Check that IMDb ratings are numbers between 0 and 10. | C26: movies!D1:D46

Sheet financials
A1: movie_id | B1: budget | C1: revenue | D1: unit | E1: currency
A2: 101 | B2: 1 | C2: 12.5 | D2: Billions | E2: INR
A3: 102 | B3: 200 | C3: 954.8 | D3: Millions | E3: USD
A4: 103 | B4: 165 | C4: 644.8 | D4: Millions | E4: USD
A5: 104 | B5: 180 | C5: 854 | D5: Millions | E5: USD
A6: 105 | B6: 250 | C6: 670 | D6: Millions | E6: USD
A7: 107 | B7: 400 | C7: 2000 | D7: Millions | E7: INR
A8: 108 | B8: 550 | C8: 4000 | D8: Millions | E8: INR
A9: 109 | B9: 390 | C9: 1360 | D9: Millions | E9: INR
A10: 110 | B10: 1.4 | C10: 3.5 | D10: Billions | E10: INR
A11: 111 | B11: 25 | C11: 73.3 | D11: Millions | E11: USD
A12: 113 | B12: 165 | C12: 701.8 | D12: Millions | E12: USD
A13: 114 | B13: 205 | C13: 365.3 | D13: Millions | E13: USD
... A45: 144 | B45: 100 | C45: 83.7 | D45: Millions | E45: USD

Sheet actors
A1: actor_id | B1: name | C1: birth_year
A2: 50 | B2: Yash | C2: 1986
A3: 51 | B3: Sanjay Dutt | C3: 1959
A4: 52 | B4: Benedict Cumberbatch | C4: 1976
A5: 53 | B5: Elizabeth Olsen | C5: 1989
A6: 54 | B6: Chris Hemsworth | C6: 1983
A7: 55 | B7: Natalie Portman | C7: 1981
A8: 56 | B8: Tom Hiddleston | C8: 1981
A9: 57 | B9: Amitabh Bachchan | C9: 1942
A10: 58 | B10: Jaya Bachchan | C10: 1948
A11: 59 | B11: Shah Rukh Khan | C11: 1965
A12: 60 | B12: Kajol | C12: 1974
A13: 61 | B13: Aamir Khan | C13: 1965
... A68: 170 | B68: Kiara Advani | C68: 1991

Sheet movie_actor
A1: movie_id | B1: actor_id
A2: 101 | B2: 50
A3: 101 | B3: 51
A4: 102 | B4: 52
A5: 102 | B5: 53
A6: 103 | B6: 54
A7: 103 | B7: 55
A8: 103 | B8: 56
A9: 104 | B9: 54
A10: 104 | B10: 56
A11: 105 | B11: 54
A12: 105 | B12: 55
A13: 106 | B13: 57
... A86: 140 | B86: 170

Sheet languages
A1: language_id | B1: name
A2: 1 | B2: Hindi
A3: 2 | B3: Telugu
A4: 3 | B4: Kannada
A5: 4 | B5: Tamil
A6: 5 | B6: English
A7: 6 | B7: French
A8: 7 | B8: Bengali
A9: 8 | B9: Gujarati

Sheet Language Summary
A1: Language Name | B1: Number of Movies | C1: Average IMDb Rating | D1: Total Profit (USD mm)
A2: English | B2: =COUNTIF(MovieFinancials!$G$2:$G$44,5) -> 23 | C2: =IFERROR(AVERAGEIFS(MovieFinancials!$E$2:$E$44,MovieFinancials!$G$2:$G$44,5,MovieFinancials!$E$2:$E$44,">0"),"") -> 7.8391304 | D2: =SUMIFS(MovieFinancials!$R$2:$R$44,MovieFinancials!$G$2:$G$44,5)-SUMIFS(MovieFinancials!$Q$2:$Q$44,MovieFinancials!$G$2:$G$44,5) -> 15472.32
A3: Hindi | B3: =COUNTIF(MovieFinancials!$G$2:$G$44,1) -> 15 | C3: =IFERROR(AVERAGEIFS(MovieFinancials!$E$2:$E$44,MovieFinancials!$G$2:$G$44,1,MovieFinancials!$E$2:$E$44,">0"),"") -> 7.1428571 | D3: =SUMIFS(MovieFinancials!$R$2:$R$44,MovieFinancials!$G$2:$G$44,1)-SUMIFS(MovieFinancials!$Q$2:$Q$44,MovieFinancials!$G$2:$G$44,1) -> 444.9875
A4: Telugu | B4: =COUNTIF(MovieFinancials!$G$2:$G$44,2) -> 3 | C4: =IFERROR(AVERAGEIFS(MovieFinancials!$E$2:$E$44,MovieFinancials!$G$2:$G$44,2,MovieFinancials!$E$2:$E$44,">0"),"") -> 7.8666667 | D4: =SUMIFS(MovieFinancials!$R$2:$R$44,MovieFinancials!$G$2:$G$44,2)-SUMIFS(MovieFinancials!$Q$2:$Q$44,MovieFinancials!$G$2:$G$44,2) -> 160
A5: Kannada | B5: =COUNTIF(MovieFinancials!$G$2:$G$44,3) -> 1 | C5: =IFERROR(AVERAGEIFS(MovieFinancials!$E$2:$E$44,MovieFinancials!$G$2:$G$44,3,MovieFinancials!$E$2:$E$44,">0"),"") -> 8.4 | D5: =SUMIFS(MovieFinancials!$R$2:$R$44,MovieFinancials!$G$2:$G$44,3)-SUMIFS(MovieFinancials!$Q$2:$Q$44,MovieFinancials!$G$2:$G$44,3) -> 143.75
A6: Bengali | B6: =COUNTIF(MovieFinancials!$G$2:$G$44,7) -> 1 | C6: =IFERROR(AVERAGEIFS(MovieFinancials!$E$2:$E$44,MovieFinancials!$G$2:$G$44,7,MovieFinancials!$E$2:$E$44,">0"),"") -> 8.3 | D6: =SUMIFS(MovieFinancials!$R$2:$R$44,MovieFinancials!$G$2:$G$44,7)-SUMIFS(MovieFinancials!$Q$2:$Q$44,MovieFinancials!$G$2:$G$44,7) -> 0.375
A7: Tamil | B7: =COUNTIF(MovieFinancials!$G$2:$G$44,4) -> 0 | C7: =IFERROR(AVERAGEIFS(MovieFinancials!$E$2:$E$44,MovieFinancials!$G$2:$G$44,4,MovieFinancials!$E$2:$E$44,">0"),"") | D7: =SUMIFS(MovieFinancials!$R$2:$R$44,MovieFinancials!$G$2:$G$44,4)-SUMIFS(MovieFinancials!$Q$2:$Q$44,MovieFinancials!$G$2:$G$44,4) -> 0
A8: French | B8: =COUNTIF(MovieFinancials!$G$2:$G$44,6) -> 0 | C8: =IFERROR(AVERAGEIFS(MovieFinancials!$E$2:$E$44,MovieFinancials!$G$2:$G$44,6,MovieFinancials!$E$2:$E$44,">0"),"") | D8: =SUMIFS(MovieFinancials!$R$2:$R$44,MovieFinancials!$G$2:$G$44,6)-SUMIFS(MovieFinancials!$Q$2:$Q$44,MovieFinancials!$G$2:$G$44,6) -> 0
A9: Gujarati | B9: =COUNTIF(MovieFinancials!$G$2:$G$44,8) -> 0 | C9: =IFERROR(AVERAGEIFS(MovieFinancials!$E$2:$E$44,MovieFinancials!$G$2:$G$44,8,MovieFinancials!$E$2:$E$44,">0"),"") | D9: =SUMIFS(MovieFinancials!$R$2:$R$44,MovieFinancials!$G$2:$G$44,8)-SUMIFS(MovieFinancials!$Q$2:$Q$44,MovieFinancials!$G$2:$G$44,8) -> 0
F20: Language Name | G20: Total Profit (USD mm)
F21: =A2 -> English | G21: =D2 -> 15472.32
F22: =A3 -> Hindi | G22: =D3 -> 444.9875
F23: =A4 -> Telugu | G23: =D4 -> 160
F24: =A5 -> Kannada | G24: =D5 -> 143.75
F25: =A6 -> Bengali | G25: =D6 -> 0.375
F26: =A7 -> Tamil | G26: =D7 -> 0
F27: =A8 -> French | G27: =D8 -> 0
F28: =A9 -> Gujarati | G28: =D9 -> 0

Sheet Check Log
A1: Check | B1: What I did | C1: Result
A2: Row count | B2: Compared total movies in MovieFinancials with total language-summary movie count | C2: Both totals matched at 43 movies
A3: One Value by hand | B3: Calculated ROI for The Godfather manually | C3: 39.42
A4: Grand total vs sum of parts | B4: Compared the movie count for each language in the Langusge Summary against the corresponding records in MovieFinancials | C4: Movies counts matched across the languages checked, confirming that the summary correactly reflects the data
A5: FIlter stress test | B5: Filtered watch verdict to show only must watch movies and checked a few IMDb ratings against the rule | C5: All displayed movies had an IMDb rating of 8 or above, confirming the formula worked correcly after filetring
